Workbook
Name Country: KDI_Dashboard!$M$5
Name Income_group: KDI_Dashboard!$D$3
Name Year: KDI_Dashboard!$G$5

Sheet Development Indicators
A1: Country Name | B1: Country Code | C1: Region | D1: IncomeGroup | E1: Year | F1: Birth rate, crude (per 1,000 people) | G1: Death rate, crude (per 1,000 people) | H1: Electric power consumption (kWh per capita) | I1: GDP (USD) | J1: GDP per capita (USD) | K1: Individuals using the Internet (% of population) | L1: Infant mortality rate (per 1,000 live births) | M1: Life expectancy at birth (years) | N1: Population density (people per sq. km of land area) | O1: Unemployment (% of total labor force) (modeled ILO estimate)
A2: Afghanistan | B2: AFG | C2: South Asia | D2: Low income | E2: 2018 | I2: 19363000000 | J2: 520.897 | L2: 47.9 | N2: 56.9378 | O2: 1.542
A3: Afghanistan | B3: AFG | C3: South Asia | D3: Low income | E3: 2017 | F3: 33.211 | G3: 6.575 | I3: 20191800000 | J3: 556.302 | K3: 13.5 | L3: 49.5 | M3: 64.13 | N3: 55.596 | O3: 1.559
A4: Afghanistan | B4: AFG | C4: South Asia | D4: Low income | E4: 2016 | F4: 33.981 | G4: 6.742 | I4: 19362600000 | J4: 547.228 | K4: 11.2 | L4: 51.2 | M4: 63.763 | N4: 54.1971 | O4: 1.634
A5: Afghanistan | B5: AFG | C5: South Asia | D5: Low income | E5: 2015 | F5: 34.809 | G5: 6.929 | I5: 19907100000 | J5: 578.466 | K5: 8.26 | L5: 53.1 | M5: 63.377 | N5: 52.7121 | O5: 1.679
A6: Afghanistan | B6: AFG | C6: South Asia | D6: Low income | E6: 2014 | F6: 35.706 | G6: 7.141 | I6: 20484900000 | J6: 613.856 | K6: 7 | L6: 55.1 | M6: 62.966 | N6: 51.1148 | O6: 1.735
A7: Afghanistan | B7: AFG | C7: South Asia | D7: Low income | E7: 2013 | F7: 36.67 | G7: 7.38 | I7: 20561100000 | J7: 637.165 | K7: 5.9 | L7: 57.3 | M7: 62.525 | N7: 49.428 | O7: 1.725
A8: Afghanistan | B8: AFG | C8: South Asia | D8: Low income | E8: 2012 | F8: 37.69 | G8: 7.645 | I8: 20001600000 | J8: 641.872 | K8: 5.45455 | L8: 59.5 | M8: 62.054 | N8: 47.7306 | O8: 1.692
A9: Afghanistan | B9: AFG | C9: South Asia | D9: Low income | E9: 2011 | F9: 38.75 | G9: 7.936 | I9: 17804300000 | J9: 591.162 | K9: 5 | L9: 61.9 | M9: 61.553 | N9: 46.1315 | O9: 1.984
A10: Afghanistan | B10: AFG | C10: South Asia | D10: Low income | E10: 2010 | F10: 39.829 | G10: 8.25 | I10: 15856600000 | J10: 543.303 | K10: 4 | L10: 64.3 | M10: 61.028 | N10: 44.7041 | O10: 2.275
A11: Afghanistan | B11: AFG | C11: South Asia | D11: Low income | E11: 2009 | F11: 40.903 | G11: 8.584 | I11: 12439100000 | J11: 438.076 | K11: 3.55 | L11: 66.8 | M11: 60.484 | N11: 43.493 | O11: 2.47
A12: Afghanistan | B12: AFG | C12: South Asia | D12: Low income | E12: 2008 | F12: 41.949 | G12: 8.932 | I12: 10109200000 | J12: 364.66 | K12: 1.84 | L12: 69.4 | M12: 59.93 | N12: 42.4628 | O12: 2.494
A13: Afghanistan | B13: AFG | C13: South Asia | D13: Low income | E13: 2007 | F13: 42.944 | G13: 9.287 | I13: 9747890000 | J13: 359.693 | K13: 1.9 | L13: 72 | M13: 59.375 | N13: 41.5105 | O13: 2.128
A14: Afghanistan | B14: AFG | C14: South Asia | D14: Low income | E14: 2006 | F14: 43.87 | G14: 9.645 | I14: 6971290000 | J14: 263.734 | K14: 2.10712 | L14: 74.7 | M14: 58.826 | N14: 40.4881 | O14: 2.825
... A18: Afghanistan | B18: AFG | C18: South Asia | D18: Low income | E18: 2002 | F18: 46.901 | G18: 11.048 | I18: 4055180000 | J18: 179.426 | K18: 0.0045614 | L18: 85.4 | M18: 56.784 | N18: 34.6181 | O18: 3.55
A19: Afghanistan | B19: AFG | C19: South Asia | D19: Low income | E19: 2001 | F19: 47.505 | G19: 11.387 | K19: 0.00472257 | L19: 88 | M19: 56.308 | N19: 33.0959 | O19: 3.426
A20: Afghanistan | B20: AFG | C20: South Asia | D20: Low income | E20: 2000 | F20: 48.021 | G20: 11.718 | L20: 90.6 | M20: 55.841 | N20: 31.8291 | O20: 3.517
A21: Afghanistan | B21: AFG | C21: South Asia | D21: Low income | E21: 1999 | F21: 48.419 | G21: 12.037 | L21: 93.1 | M21: 55.376 | N21: 30.8961 | O21: 3.606
A22: Afghanistan | B22: AFG | C22: South Asia | D22: Low income | E22: 1998 | F22: 48.688 | G22: 12.348 | L22: 95.7 | M22: 54.906 | N22: 30.2328 | O22: 3.536
A23: Afghanistan | B23: AFG | C23: South Asia | D23: Low income | E23: 1997 | F23: 48.833 | G23: 12.655 | L23: 98.4 | M23: 54.424 | N23: 29.6497 | O23: 3.603
A24: Afghanistan | B24: AFG | C24: South Asia | D24: Low income | E24: 1996 | F24: 48.87 | G24: 12.964 | L24: 101.1 | M24: 53.924 | N24: 28.8782 | O24: 3.621
A25: Afghanistan | B25: AFG | C25: South Asia | D25: Low income | E25: 1995 | F25: 48.835 | G25: 13.282 | L25: 104 | M25: 53.398 | N25: 27.7405 | O25: 3.653
A26: Afghanistan | B26: AFG | C26: South Asia | D26: Low income | E26: 1994 | F26: 48.77 | G26: 13.616 | L26: 107.1 | M26: 52.842 | N26: 26.1553 | O26: 3.612
A27: Afghanistan | B27: AFG | C27: South Asia | D27: Low income | E27: 1993 | F27: 48.717 | G27: 13.974 | L27: 110.4 | M27: 52.256 | N27: 24.2266 | O27: 3.463
A28: Afghanistan | B28: AFG | C28: South Asia | D28: Low income | E28: 1992 | F28: 48.709 | G28: 14.362 | L28: 113.7 | M28: 51.641 | N28: 22.1878 | O28: 3.173
A29: Afghanistan | B29: AFG | C29: South Asia | D29: Low income | E29: 1991 | F29: 48.763 | G29: 14.783 | L29: 117.3 | M29: 50.999 | N29: 20.3704 | O29: 2.976
A30: Afghanistan | B30: AFG | C30: South Asia | D30: Low income | E30: 1990 | F30: 48.88 | G30: 15.241 | K30: 0 | L30: 121.1 | M30: 50.331 | N30: 19.0122
A31: Afghanistan | B31: AFG | C31: South Asia | D31: Low income | E31: 1989 | F31: 49.048 | G31: 15.738 | L31: 125.1 | M31: 49.64 | N31: 18.1798
A32: Afghanistan | B32: AFG | C32: South Asia | D32: Low income | E32: 1988 | F32: 49.236 | G32: 16.268 | L32: 129.2 | M32: 48.93 | N32: 17.7956
A33: Afghanistan | B33: AFG | C33: South Asia | D33: Low income | E33: 1987 | F33: 49.418 | G33: 16.826 | L33: 133.3 | M33: 48.211 | N33: 17.7749
A34: Afghanistan | B34: AFG | C34: South Asia | D34: Low income | E34: 1986 | F34: 49.586 | G34: 17.406 | L34: 137.5 | M34: 47.486 | N34: 17.9766
A35: Afghanistan | B35: AFG | C35: South Asia | D35: Low income | E35: 1985 | F35: 49.735 | G35: 18.005 | L35: 141.6 | M35: 46.761 | N35: 18.286
A36: Afghanistan | B36: AFG | C36: South Asia | D36: Low income | E36: 1984 | F36: 49.865 | G36: 18.618 | L36: 145.7 | M36: 46.04 | N36: 18.6936
A37: Afghanistan | B37: AFG | C37: South Asia | D37: Low income | E37: 1983 | F37: 49.984 | G37: 19.24 | L37: 149.8 | M37: 45.324 | N37: 19.2043
A38: Afghanistan | B38: AFG | C38: South Asia | D38: Low income | E38: 1982 | F38: 50.098 | G38: 19.865 | L38: 154.1 | M38: 44.617 | N38: 19.7325
A39: Afghanistan | B39: AFG | C39: South Asia | D39: Low income | E39: 1981 | F39: 50.21 | G39: 20.49 | I39: 3478790000 | J39: 264.111 | L39: 158.4 | M39: 43.923 | N39: 20.1753
A40: Afghanistan | B40: AFG | C40: South Asia | D40: Low income | E40: 1980 | F40: 50.321 | G40: 21.109 | I40: 3641720000 | J40: 272.655 | L40: 162.7 | M40: 43.244 | N40: 20.4585
A41: Afghanistan | B41: AFG | C41: South Asia | D41: Low income | E41: 1979 | F41: 50.436 | G41: 21.72 | I41: 3697940000 | J41: 275.738 | L41: 167 | M41: 42.585 | N41: 20.542
A42: Afghanistan | B42: AFG | C42: South Asia | D42: Low income | E42: 1978 | F42: 50.555 | G42: 22.324 | I42: 3300000000 | J42: 247.354 | L42: 171.2 | M42: 41.944 | N42: 20.435
A43: Afghanistan | B43: AFG | C43: South Asia | D43: Low income | E43: 1977 | F43: 50.678 | G43: 22.92 | I43: 2953330000 | J43: 224.225 | L43: 175.4 | M43: 41.32 | N43: 20.1748
...

Sheet KDI_Dashboard
A1: ="Key Development Indicators- "&Country&"("&Year&")" -> Key Development Indicators- Global(2001)
G4: Year | M4: Country
G5: 2001 | M5: Global
B8: Infant Mortality Rate over Years | F8: Life Expectancy over Years | L8: GDP per Capita Trend over Years | P8: Unemployment Rate over Years

Sheet Data Validation
I2: Global | J2: {=IFERROR(MEDIAN( IF( (World[Year]=Year)* (World[Infant mortality rate (per 1,000 live births)]<>0), World[Infant mortality rate (per 1,000 live births)])),"No Value")} -> 25.15 | K2: {=IFERROR(MEDIAN( IF( (World[Year]=Year)* (World[Life expectancy at birth (years)]<>0), World[Life expectancy at birth (years)])),"No data")} -> 70.7735 | L2: {=IFERROR(MEDIAN( IF( (World[Year]=Year)* (World[GDP per capita (USD)]<>0), World[GDP per capita (USD)])),"No Value")} -> 1925.54 | M2: {=IFERROR(MEDIAN( IF( (World[Year]=Year)* (World[Unemployment (% of total labor force) (modeled ILO estimate)]<>0), World[Unemployment (% of total labor force) (modeled ILO estimate)])),"No Value")} -> 7.2405 | N2: {=IFERROR(MEDIAN( IF( (World[Year]=Year-1)* (World[Infant mortality rate (per 1,000 live births)]<>0), World[Infant mortality rate (per 1,000 live births)])),"No Value")} -> 25.55 | O2: {=IFERROR(MEDIAN( IF( (World[Year]=Year-1)* (World[Life expectancy at birth (years)]<>0), World[Life expectancy at birth (years)])),"No Value")} -> 70.36585 | P2: {=IFERROR(MEDIAN( IF( (World[Year]=Year-1)* (World[GDP per capita (USD)]<>0), World[GDP per capita (USD)])),"No Value")} -> 2010 | Q2: {=IFERROR(MEDIAN( IF( (World[Year]=Year-1)* (World[Unemployment (% of total labor force) (modeled ILO estimate)]<>0), World[Unemployment (% of total labor force) (modeled ILO estimate)])),"No Value")} -> 6.9635 | R2: {=IFERROR(MEDIAN( IF( (World[Year]=Year-2)* (World[Infant mortality rate (per 1,000 live births)]<>0), World[Infant mortality rate (per 1,000 live births)])),"No Value")} -> 26.45 | S2: {=IFERROR(MEDIAN( IF( (World[Year]=Year-2)* (World[Life expectancy at birth (years)]<>0), World[Life expectancy at birth (years)])),"No Value")} -> 69.769 | T2: {=IFERROR(MEDIAN( IF( (World[Year]=Year-2)* (World[GDP per capita (USD)]<>0), World[GDP per capita (USD)])),"No Value")} -> 2141.46 | U2: {=IFERROR(MEDIAN( IF( (World[Year]=Year-2)* (World[Unemployment (% of total labor force) (modeled ILO estimate)]<>0), World[Unemployment (% of total labor force) (modeled ILO estimate)])),"No Value")} -> 7.5165
G3: {=_xlfn.UNIQUE(World[Year])} -> 2018 | I3: {=_xlfn.UNIQUE(World[Country Name])} -> Afghanistan | J3: {=IFERROR(MEDIAN( IF( (World[Country Name]=$I3)* (World[Year]=Year)* (World[Infant mortality rate (per 1,000 live births)]<>0), World[Infant mortality rate (per 1,000 live births)])),"No Value")} -> 88 | K3: {=IFERROR(MEDIAN( IF( (World[Country Name]=$I3)* (World[Year]=Year)* (World[Life expectancy at birth (years)]<>0), World[Life expectancy at birth (years)])),"No data")} -> 56.308 | L3: {=IFERROR(MEDIAN( IF( (World[Country Name]=$I3)* (World[Year]=Year)* (World[GDP per capita (USD)]<>0), World[GDP per capita (USD)])),"No Value")} -> No Value | M3: {=IFERROR(MEDIAN( IF( (World[Country Name]=$I3)* (World[Year]=Year)* (World[Unemployment (% of total labor force) (modeled ILO estimate)]<>0), World[Unemployment (% of total labor force) (modeled ILO estimate)])),"No Value")} -> 3.426 | N3: {=IFERROR(MEDIAN( IF( (World[Country Name]=$I3)* (World[Year]=Year-1)* (World[Infant mortality rate (per 1,000 live births)]<>0), World[Infant mortality rate (per 1,000 live births)])),"No Value")} -> 90.6 | O3: {=IFERROR(MEDIAN( IF( (World[Country Name]=$I3)* (World[Year]=Year-1)* (World[Life expectancy at birth (years)]<>0), World[Life expectancy at birth (years)])),"No Value")} -> 55.841 | P3: {=IFERROR(MEDIAN( IF( (World[Country Name]=$I3)* (World[Year]=Year-1)* (World[GDP per capita (USD)]<>0), World[GDP per capita (USD)])),"No Value")} -> No Value | Q3: {=IFERROR(MEDIAN( IF( (World[Country Name]=$I3)* (World[Year]=Year-1)* (World[Unemployment (% of total labor force) (modeled ILO estimate)]<>0), World[Unemployment (% of total labor force) (modeled ILO estimate)])),"No Value")} -> 3.517 | R3: {=IFERROR(MEDIAN( IF( (World[Country Name]=$I3)* (World[Year]=Year-2)* (World[Infant mortality rate (per 1,000 live births)]<>0), World[Infant mortality rate (per 1,000 live births)])),"No Value")} -> 93.1 | S3: {=IFERROR(MEDIAN( IF( (World[Country Name]=$I3)* (World[Year]=Year-2)* (World[Life expectancy at birth (years)]<>0), World[Life expectancy at birth (years)])),"No Value")} -> 55.376 | T3: {=IFERROR(MEDIAN( IF( (World[Country Name]=$I3)* (World[Year]=Year-2)* (World[GDP per capita (USD)]<>0), World[GDP per capita (USD)])),"No Value")} -> No Value | U3: {=IFERROR(MEDIAN( IF( (World[Country Name]=$I3)* (World[Year]=Year-2)* (World[Unemployment (% of total labor force) (modeled ILO estimate)]<>0), World[Unemployment (% of total labor force) (modeled ILO estimate)])),"No Value")} -> 3.606
G4: 2017 | I4: Albania | J4: {=IFERROR(MEDIAN( IF( (World[Country Name]=$I4)* (World[Year]=Year)* (World[Infant mortality rate (per 1,000 live births)]<>0), World[Infant mortality rate (per 1,000 live births)])),"No Value")} -> 21.8 | K4: {=IFERROR(MEDIAN( IF( (World[Country Name]=$I4)* (World[Year]=Year)* (World[Life expectancy at birth (years)]<>0), World[Life expectancy at birth (years)])),"No data")} -> 74.288 | L4: {=IFERROR(MEDIAN( IF( (World[Country Name]=$I4)* (World[Year]=Year)* (World[GDP per capita (USD)]<>0), World[GDP per capita (USD)])),"No Value")} -> 1281.66 | M4: {=IFERROR(MEDIAN( IF( (World[Country Name]=$I4)* (World[Year]=Year)* (World[Unemployment (% of total labor force) (modeled ILO estimate)]<>0), World[Unemployment (% of total labor force) (modeled ILO estimate)])),"No Value")} -> 17.411 | N4: {=IFERROR(MEDIAN( IF( (World[Country Name]=$I4)* (World[Year]=Year-1)* (World[Infant mortality rate (per 1,000 live births)]<>0), World[Infant mortality rate (per 1,000 live births)])),"No Value")} -> 23 | O4: {=IFERROR(MEDIAN( IF( (World[Country Name]=$I4)* (World[Year]=Year-1)* (World[Life expectancy at birth (years)]<>0), World[Life expectancy at birth (years)])),"No Value")} -> 73.955 | P4: {=IFERROR(MEDIAN( IF( (World[Country Name]=$I4)* (World[Year]=Year-1)* (World[GDP per capita (USD)]<>0), World[GDP per capita (USD)])),"No Value")} -> 1126.68 | Q4: {=IFERROR(MEDIAN( IF( (World[Country Name]=$I4)* (World[Year]=Year-1)* (World[Unemployment (% of total labor force) (modeled ILO estimate)]<>0), World[Unemployment (% of total labor force) (modeled ILO estimate)])),"No Value")} -> 17.767 | R4: {=IFERROR(MEDIAN( IF( (World[Country Name]=$I4)* (World[Year]=Year-2)* (World[Infant mortality rate (per 1,000 live births)]<>0), World[Infant mortality rate (per 1,000 live births)])),"No Value")} -> 24.2 | S4: {=IFERROR(MEDIAN( IF( (World[Country Name]=$I4)* (World[Year]=Year-2)* (World[Life expectancy at birth (years)]<>0), World[Life expectancy at birth (years)])),"No Value")} -> 73.587 | T4: {=IFERROR(MEDIAN( IF( (World[Country Name]=$I4)* (World[Year]=Year-2)* (World[GDP per capita (USD)]<>0), World[GDP per capita (USD)])),"No Value")} -> 1033.24 | U4: {=IFERROR(MEDIAN( IF( (World[Country Name]=$I4)* (World[Year]=Year-2)* (World[Unemployment (% of total labor force) (modeled ILO estimate)]<>0), World[Unemployment (% of total labor force) (modeled ILO estimate)])),"No Value")} -> 18.569
G5: 2016 | I5: Algeria | J5: {=IFERROR(MEDIAN( IF( (World[Country Name]=$I5)* (World[Year]=Year)* (World[Infant mortality rate (per 1,000 live births)]<>0), World[Infant mortality rate (per 1,000 live births)])),"No Value")} -> 33.3 | K5: {=IFERROR(MEDIAN( IF( (World[Country Name]=$I5)* (World[Year]=Year)* (World[Life expectancy at birth (years)]<>0), World[Life expectancy at birth (years)])),"No data")} -> 71.116 | L5: {=IFERROR(MEDIAN( IF( (World[Country Name]=$I5)* (World[Year]=Year)* (World[GDP per capita (USD)]<>0), World[GDP per capita (USD)])),"No Value")} -> 1740.61 | M5: {=IFERROR(MEDIAN( IF( (World[Country Name]=$I5)* (World[Year]=Year)* (World[Unemployment (% of total labor force) (modeled ILO estimate)]<>0), World[Unemployment (% of total labor force) (modeled ILO estimate)])),"No Value")} -> 27.3 | N5: {=IFERROR(MEDIAN( IF( (World[Country Name]=$I5)* (World[Year]=Year-1)* (World[Infant mortality rate (per 1,000 live births)]<>0), World[Infant mortality rate (per 1,000 live births)])),"No Value")} -> 33.9 | O5: {=IFERROR(MEDIAN( IF( (World[Country Name]=$I5)* (World[Year]=Year-1)* (World[Life expectancy at birth (years)]<>0), World[Life expectancy at birth (years)])),"No Value")} -> 70.64 | P5: {=IFERROR(MEDIAN( IF( (World[Country Name]=$I5)* (World[Year]=Year-1)* (World[GDP per capita (USD)]<>0), World[GDP per capita (USD)])),"No Value")} -> 1765.02 | Q5: {=IFERROR(MEDIAN( IF( (World[Country Name]=$I5)* (World[Year]=Year-1)* (World[Unemployment (% of total labor force) (modeled ILO estimate)]<>0), World[Unemployment (% of total labor force) (modeled ILO estimate)])),"No Value")} -> 29.77 | R5: {=IFERROR(MEDIAN( IF( (World[Country Name]=$I5)* (World[Year]=Year-2)* (World[Infant mortality rate (per 1,000 live births)]<>0), World[Infant mortality rate (per 1,000 live births)])),"No Value")} -> 34.4 | S5: {=IFERROR(MEDIAN( IF( (World[Country Name]=$I5)* (World[Year]=Year-2)* (World[Life expectancy at birth (years)]<>0), World[Life expectancy at birth (years)])),"No Value")} -> 70.183 | T5: {=IFERROR(MEDIAN( IF( (World[Country Name]=$I5)* (World[Year]=Year-2)* (World[GDP per capita (USD)]<>0), World[GDP per capita (USD)])),"No Value")} -> 1588.35 | U5: {=IFERROR(MEDIAN( IF( (World[Country Name]=$I5)* (World[Year]=Year-2)* (World[Unemployment (% of total labor force) (modeled ILO estimate)]<>0), World[Unemployment (% of total labor force) (modeled ILO estimate)])),"No Value")} -> 28.448
G6: 2015 | I6: American Samoa | J6: {=IFERROR(MEDIAN( IF( (World[Country Name]=$I6)* (World[Year]=Year)* (World[Infant mortality rate (per 1,000 live births)]<>0), World[Infant mortality rate (per 1,000 live births)])),"No Value")} -> No Value | K6: {=IFERROR(MEDIAN( IF( (World[Country Name]=$I6)* (World[Year]=Year)* (World[Life expectancy at birth (years)]<>0), World[Life expectancy at birth (years)])),"No data")} -> No data | L6: {=IFERROR(MEDIAN( IF( (World[Country Name]=$I6)* (World[Year]=Year)* (World[GDP per capita (USD)]<>0), World[GDP per capita (USD)])),"No Value")} -> No Value | M6: {=IFERROR(MEDIAN( IF( (World[Country Name]=$I6)* (World[Year]=Year)* (World[Unemployment (% of total labor force) (modeled ILO estimate)]<>0), World[Unemployment (% of total labor force) (modeled ILO estimate)])),"No Value")} -> No Value | N6: {=IFERROR(MEDIAN( IF( (World[Country Name]=$I6)* (World[Year]=Year-1)* (World[Infant mortality rate (per 1,000 live births)]<>0), World[Infant mortality rate (per 1,000 live births)])),"No Value")} -> No Value | O6: {=IFERROR(MEDIAN( IF( (World[Country Name]=$I6)* (World[Year]=Year-1)* (World[Life expectancy at birth (years)]<>0), World[Life expectancy at birth (years)])),"No Value")} -> No Value | P6: {=IFERROR(MEDIAN( IF( (World[Country Name]=$I6)* (World[Year]=Year-1)* (World[GDP per capita (USD)]<>0), World[GDP per capita (USD)])),"No Value")} -> No Value | Q6: {=IFERROR(MEDIAN( IF( (World[Country Name]=$I6)* (World[Year]=Year-1)* (World[Unemployment (% of total labor force) (modeled ILO estimate)]<>0), World[Unemployment (% of total labor force) (modeled ILO estimate)])),"No Value")} -> No Value | R6: {=IFERROR(MEDIAN( IF( (World[Country Name]=$I6)* (World[Year]=Year-2)* (World[Infant mortality rate (per 1,000 live births)]<>0), World[Infant mortality rate (per 1,000 live births)])),"No Value")} -> No Value | S6: {=IFERROR(MEDIAN( IF( (World[Country Name]=$I6)* (World[Year]=Year-2)* (World[Life expectancy at birth (years)]<>0), World[Life expectancy at birth (years)])),"No Value")} -> No Value | T6: {=IFERROR(MEDIAN( IF( (World[Country Name]=$I6)* (World[Year]=Year-2)* (World[GDP per capita (USD)]<>0), World[GDP per capita (USD)])),"No Value")} -> No Value | U6: {=IFERROR(MEDIAN( IF( (World[Country Name]=$I6)* (World[Year]=Year-2)* (World[Unemployment (% of total labor force) (modeled ILO estimate)]<>0), World[Unemployment (% of total labor force) (modeled ILO estimate)])),"No Value")} -> No Value
G7: 2014 | I7: Andorra | J7: {=IFERROR(MEDIAN( IF( (World[Country Name]=$I7)* (World[Year]=Year)* (World[Infant mortality rate (per 1,000 live births)]<>0), World[Infant mortality rate (per 1,000 live births)])),"No Value")} -> 5.7 | K7: {=IFERROR(MEDIAN( IF( (World[Country Name]=$I7)* (World[Year]=Year)* (World[Life expectancy at birth (years)]<>0), World[Life expectancy at birth (years)])),"No data")} -> No data | L7: {=IFERROR(MEDIAN( IF( (World[Country Name]=$I7)* (World[Year]=Year)* (World[GDP per capita (USD)]<>0), World[GDP per capita (USD)])),"No Value")} -> 22228.8 | M7: {=IFERROR(MEDIAN( IF( (World[Country Name]=$I7)* (World[Year]=Year)* (World[Unemployment (% of total labor force) (modeled ILO estimate)]<>0), World[Unemployment (% of total labor force) (modeled ILO estimate)])),"No Value")} -> No Value | N7: {=IFERROR(MEDIAN( IF( (World[Country Name]=$I7)* (World[Year]=Year-1)* (World[Infant mortality rate (per 1,000 live births)]<>0), World[Infant mortality rate (per 1,000 live births)])),"No Value")} -> 5.9 | O7: {=IFERROR(MEDIAN( IF( (World[Country Name]=$I7)* (World[Year]=Year-1)* (World[Life expectancy at birth (years)]<>0), World[Life expectancy at birth (years)])),"No Value")} -> No Value | P7: {=IFERROR(MEDIAN( IF( (World[Country Name]=$I7)* (World[Year]=Year-1)* (World[GDP per capita (USD)]<>0), World[GDP per capita (USD)])),"No Value")} -> 21936.5 | Q7: {=IFERROR(MEDIAN( IF( (World[Country Name]=$I7)* (World[Year]=Year-1)* (World[Unemployment (% of total labor force) (modeled ILO estimate)]<>0), World[Unemployment (% of total labor force) (modeled ILO estimate)])),"No Value")} -> No Value | R7: {=IFERROR(MEDIAN( IF( (World[Country Name]=$I7)* (World[Year]=Year-2)* (World[Infant mortality rate (per 1,000 live births)]<>0), World[Infant mortality rate (per 1,000 live births)])),"No Value")} -> 6.2 | S7: {=IFERROR(MEDIAN( IF( (World[Country Name]=$I7)* (World[Year]=Year-2)* (World[Life expectancy at birth (years)]<>0), World[Life expectancy at birth (years)])),"No Value")} -> No Value | T7: {=IFERROR(MEDIAN( IF( (World[Country Name]=$I7)* (World[Year]=Year-2)* (World[GDP per capita (USD)]<>0), World[GDP per capita (USD)])),"No Value")} -> 19261.7 | U7: {=IFERROR(MEDIAN( IF( (World[Country Name]=$I7)* (World[Year]=Year-2)* (World[Unemployment (% of total labor force) (modeled ILO estimate)]<>0), World[Unemployment (% of total labor force) (modeled ILO estimate)])),"No Value")} -> No Value
G8: 2013 | I8: Angola | J8: {=IFERROR(MEDIAN( IF( (World[Country Name]=$I8)* (World[Year]=Year)* (World[Infant mortality rate (per 1,000 live births)]<>0), World[Infant mortality rate (per 1,000 live births)])),"No Value")} -> 118.9 | K8: {=IFERROR(MEDIAN( IF( (World[Country Name]=$I8)* (World[Year]=Year)* (World[Life expectancy at birth (years)]<>0), World[Life expectancy at birth (years)])),"No data")} -> 47.059 | L8: {=IFERROR(MEDIAN( IF( (World[Country Name]=$I8)* (World[Year]=Year)* (World[GDP per capita (USD)]<>0), World[GDP per capita (USD)])),"No Value")} -> 527.334 | M8: {=IFERROR(MEDIAN( IF( (World[Country Name]=$I8)* (World[Year]=Year)* (World[Unemployment (% of total labor force) (modeled ILO estimate)]<>0), World[Unemployment (% of total labor force) (modeled ILO estimate)])),"No Value")} -> 23.115 | N8: {=IFERROR(MEDIAN( IF( (World[Country Name]=$I8)* (World[Year]=Year-1)* (World[Infant mortality rate (per 1,000 live births)]<>0), World[Infant mortality rate (per 1,000 live births)])),"No Value")} -> 122.2 | O8: {=IFERROR(MEDIAN( IF( (World[Country Name]=$I8)* (World[Year]=Year-1)* (World[Life expectancy at birth (years)]<>0), World[Life expectancy at birth (years)])),"No Value")} -> 46.522 | P8: {=IFERROR(MEDIAN( IF( (World[Country Name]=$I8)* (World[Year]=Year-1)* (World[GDP per capita (USD)]<>0), World[GDP per capita (USD)])),"No Value")} -> 556.836 | Q8: {=IFERROR(MEDIAN( IF( (World[Country Name]=$I8)* (World[Year]=Year-1)* (World[Unemployment (% of total labor force) (modeled ILO estimate)]<>0), World[Unemployment (% of total labor force) (modeled ILO estimate)])),"No Value")} -> 22.885 | R8: {=IFERROR(MEDIAN( IF( (World[Country Name]=$I8)* (World[Year]=Year-2)* (World[Infant mortality rate (per 1,000 live births)]<>0), World[Infant mortality rate (per 1,000 live births)])),"No Value")} -> 125.1 | S8: {=IFERROR(MEDIAN( IF( (World[Country Name]=$I8)* (World[Year]=Year-2)* (World[Life expectancy at birth (years)]<>0), World[Life expectancy at birth (years)])),"No Value")} -> 46.093 | T8: {=IFERROR(MEDIAN( IF( (World[Country Name]=$I8)* (World[Year]=Year-2)* (World[GDP per capita (USD)]<>0), World[GDP per capita (USD)])),"No Value")} -> 387.784 | U8: {=IFERROR(MEDIAN( IF( (World[Country Name]=$I8)* (World[Year]=Year-2)* (World[Unemployment (% of total labor force) (modeled ILO estimate)]<>0), World[Unemployment (% of total labor force) (modeled ILO estimate)])),"No Value")} -> 20.897
G9: 2012 | I9: Antigua and Barbuda | J9: {=IFERROR(MEDIAN( IF( (World[Country Name]=$I9)* (World[Year]=Year)* (World[Infant mortality rate (per 1,000 live births)]<>0), World[Infant mortality rate (per 1,000 live births)])),"No Value")} -> 12.5 | K9: {=IFERROR(MEDIAN( IF( (World[Country Name]=$I9)* (World[Year]=Year)* (World[Life expectancy at birth (years)]<>0), World[Life expectancy at birth (years)])),"No data")} -> 74.171 | L9: {=IFERROR(MEDIAN( IF( (World[Country Name]=$I9)* (World[Year]=Year)* (World[GDP per capita (USD)]<>0), World[GDP per capita (USD)])),"No Value")} -> 10370.7 | M9: {=IFERROR(MEDIAN( IF( (World[Country Name]=$I9)* (World[Year]=Year)* (World[Unemployment (% of total labor force) (modeled ILO estimate)]<>0), World[Unemployment (% of total labor force) (modeled ILO estimate)])),"No Value")} -> No Value | N9: {=IFERROR(MEDIAN( IF( (World[Country Name]=$I9)* (World[Year]=Year-1)* (World[Infant mortality rate (per 1,000 live births)]<>0), World[Infant mortality rate (per 1,000 live births)])),"No Value")} -> 13.1 | O9: {=IFERROR(MEDIAN( IF( (World[Country Name]=$I9)* (World[Year]=Year-1)* (World[Life expectancy at birth (years)]<>0), World[Life expectancy at birth (years)])),"No Value")} -> 73.94 | P9: {=IFERROR(MEDIAN( IF( (World[Country Name]=$I9)* (World[Year]=Year-1)* (World[GDP per capita (USD)]<>0), World[GDP per capita (USD)])),"No Value")} -> 10920.8 | Q9: {=IFERROR(MEDIAN( IF( (World[Country Name]=$I9)* (World[Year]=Year-1)* (World[Unemployment (% of total labor force) (modeled ILO estimate)]<>0), World[Unemployment (% of total labor force) (modeled ILO estimate)])),"No Value")} -> No Value | R9: {=IFERROR(MEDIAN( IF( (World[Country Name]=$I9)* (World[Year]=Year-2)* (World[Infant mortality rate (per 1,000 live births)]<>0), World[Infant mortality rate (per 1,000 live births)])),"No Value")} -> 13.9 | S9: {=IFERROR(MEDIAN( IF( (World[Country Name]=$I9)* (World[Year]=Year-2)* (World[Life expectancy at birth (years)]<>0), World[Life expectancy at birth (years)])),"No Value")} -> 73.705 | T9: {=IFERROR(MEDIAN( IF( (World[Country Name]=$I9)* (World[Year]=Year-2)* (World[GDP per capita (USD)]<>0), World[GDP per capita (USD)])),"No Value")} -> 10260.6 | U9: {=IFERROR(MEDIAN( IF( (World[Country Name]=$I9)* (World[Year]=Year-2)* (World[Unemployment (% of total labor force) (modeled ILO estimate)]<>0), World[Unemployment (% of total labor force) (modeled ILO estimate)])),"No Value")} -> No Value
G10: 2011 | I10: Argentina | J10: {=IFERROR(MEDIAN( IF( (World[Country Name]=$I10)* (World[Year]=Year)* (World[Infant mortality rate (per 1,000 live births)]<>0), World[Infant mortality rate (per 1,000 live births)])),"No Value")} -> 16.9 | K10: {=IFERROR(MEDIAN( IF( (World[Country Name]=$I10)* (World[Year]=Year)* (World[Life expectancy at birth (years)]<>0), World[Life expectancy at birth (years)])),"No data")} -> 73.755 | L10: {=IFERROR(MEDIAN( IF( (World[Country Name]=$I10)* (World[Year]=Year)* (World[GDP per capita (USD)]<>0), World[GDP per capita (USD)])),"No Value")} -> 7208.37 | M10: {=IFERROR(MEDIAN( IF( (World[Country Name]=$I10)* (World[Year]=Year)* (World[Unemployment (% of total labor force) (modeled ILO estimate)]<>0), World[Unemployment (% of total labor force) (modeled ILO estimate)])),"No Value")} -> 17.32 | N10: {=IFERROR(MEDIAN( IF( (World[Country Name]=$I10)* (World[Year]=Year-1)* (World[Infant mortality rate (per 1,000 live births)]<>0), World[Infant mortality rate (per 1,000 live births)])),"No Value")} -> 17.5 | O10: {=IFERROR(MEDIAN( IF( (World[Country Name]=$I10)* (World[Year]=Year-1)* (World[Life expectancy at birth (years)]<>0), World[Life expectancy at birth (years)])),"No Value")} -> 73.576 | P10: {=IFERROR(MEDIAN( IF( (World[Country Name]=$I10)* (World[Year]=Year-1)* (World[GDP per capita (USD)]<>0), World[GDP per capita (USD)])),"No Value")} -> 7708.1 | Q10: {=IFERROR(MEDIAN( IF( (World[Country Name]=$I10)* (World[Year]=Year-1)* (World[Unemployment (% of total labor force) (modeled ILO estimate)]<>0), World[Unemployment (% of total labor force) (modeled ILO estimate)])),"No Value")} -> 15 | R10: {=IFERROR(MEDIAN( IF( (World[Country Name]=$I10)* (World[Year]=Year-2)* (World[Infant mortality rate (per 1,000 live births)]<>0), World[Infant mortality rate (per 1,000 live births)])),"No Value")} -> 18.2 | S10: {=IFERROR(MEDIAN( IF( (World[Country Name]=$I10)* (World[Year]=Year-2)* (World[Life expectancy at birth (years)]<>0), World[Life expectancy at birth (years)])),"No Value")} -> 73.396 | T10: {=IFERROR(MEDIAN( IF( (World[Country Name]=$I10)* (World[Year]=Year-2)* (World[GDP per capita (USD)]<>0), World[GDP per capita (USD)])),"No Value")} -> 7774.74 | U10: {=IFERROR(MEDIAN( IF( (World[Country Name]=$I10)* (World[Year]=Year-2)* (World[Unemployment (% of total labor force) (modeled ILO estimate)]<>0), World[Unemployment (% of total labor force) (modeled ILO estimate)])),"No Value")} -> 14.05
G11: 2010 | I11: Armenia | J11: {=IFERROR(MEDIAN( IF( (World[Country Name]=$I11)* (World[Year]=Year)* (World[Infant mortality rate (per 1,000 live births)]<>0), World[Infant mortality rate (per 1,000 live births)])),"No Value")} -> 25.8 | K11: {=IFERROR(MEDIAN( IF( (World[Country Name]=$I11)* (World[Year]=Year)* (World[Life expectancy at birth (years)]<>0), World[Life expectancy at birth (years)])),"No data")} -> 71.8 | L11: {=IFERROR(MEDIAN( IF( (World[Country Name]=$I11)* (World[Year]=Year)* (World[GDP per capita (USD)]<>0), World[GDP per capita (USD)])),"No Value")} -> 694.423 | M11: {=IFERROR(MEDIAN( IF( (World[Country Name]=$I11)* (World[Year]=Year)* (World[Unemployment (% of total labor force) (modeled ILO estimate)]<>0), World[Unemployment (% of total labor force) (modeled ILO estimate)])),"No Value")} -> 11.439 | N11: {=IFERROR(MEDIAN( IF( (World[Country Name]=$I11)* (World[Year]=Year-1)* (World[Infant mortality rate (per 1,000 live births)]<>0), World[Infant mortality rate (per 1,000 live births)])),"No Value")} -> 27.1 | O11: {=IFERROR(MEDIAN( IF( (World[Country Name]=$I11)* (World[Year]=Year-1)* (World[Life expectancy at birth (years)]<>0), World[Life expectancy at birth (years)])),"No Value")} -> 71.409 | P11: {=IFERROR(MEDIAN( IF( (World[Country Name]=$I11)* (World[Year]=Year-1)* (World[GDP per capita (USD)]<>0), World[GDP per capita (USD)])),"No Value")} -> 622.742 | Q11: {=IFERROR(MEDIAN( IF( (World[Country Name]=$I11)* (World[Year]=Year-1)* (World[Unemployment (% of total labor force) (modeled ILO estimate)]<>0), World[Unemployment (% of total labor force) (modeled ILO estimate)])),"No Value")} -> 11.253 | R11: {=IFERROR(MEDIAN( IF( (World[Country Name]=$I11)* (World[Year]=Year-2)* (World[Infant mortality rate (per 1,000 live births)]<>0), World[Infant mortality rate (per 1,000 live births)])),"No Value")} -> 28.4 | S11: {=IFERROR(MEDIAN( IF( (World[Country Name]=$I11)* (World[Year]=Year-2)* (World[Life expectancy at birth (years)]<>0), World[Life expectancy at birth (years)])),"No Value")} -> 70.944 | T11: {=IFERROR(MEDIAN( IF( (World[Country Name]=$I11)* (World[Year]=Year-2)* (World[GDP per capita (USD)]<>0), World[GDP per capita (USD)])),"No Value")} -> 597.433 | U11: {=IFERROR(MEDIAN( IF( (World[Country Name]=$I11)* (World[Year]=Year-2)* (World[Unemployment (% of total labor force) (modeled ILO estimate)]<>0), World[Unemployment (% of total labor force) (modeled ILO estimate)])),"No Value")} -> 11.2
G12: 2009 | I12: Aruba | J12: {=IFERROR(MEDIAN( IF( (World[Country Name]=$I12)* (World[Year]=Year)* (World[Infant mortality rate (per 1,000 live births)]<>0), World[Infant mortality rate (per 1,000 live births)])),"No Value")} -> No Value | K12: {=IFERROR(MEDIAN( IF( (World[Country Name]=$I12)* (World[Year]=Year)* (World[Life expectancy at birth (years)]<>0), World[Life expectancy at birth (years)])),"No data")} -> 73.853 | L12: {=IFERROR(MEDIAN( IF( (World[Country Name]=$I12)* (World[Year]=Year)* (World[GDP per capita (USD)]<>0), World[GDP per capita (USD)])),"No Value")} -> 20669 | M12: {=IFERROR(MEDIAN( IF( (World[Country Name]=$I12)* (World[Year]=Year)* (World[Unemployment (% of total labor force) (modeled ILO estimate)]<>0), World[Unemployment (% of total labor force) (modeled ILO estimate)])),"No Value")} -> No Value | N12: {=IFERROR(MEDIAN( IF( (World[Country Name]=$I12)* (World[Year]=Year-1)* (World[Infant mortality rate (per 1,000 live births)]<>0), World[Infant mortality rate (per 1,000 live births)])),"No Value")} -> No Value | O12: {=IFERROR(MEDIAN( IF( (World[Country Name]=$I12)* (World[Year]=Year-1)* (World[Life expectancy at birth (years)]<>0), World[Life expectancy at birth (years)])),"No Value")} -> 73.787 | P12: {=IFERROR(MEDIAN( IF( (World[Country Name]=$I12)* (World[Year]=Year-1)* (World[GDP per capita (USD)]<>0), World[GDP per capita (USD)])),"No Value")} -> 20620.7 | Q12: {=IFERROR(MEDIAN( IF( (World[Country Name]=$I12)* (World[Year]=Year-1)* (World[Unemployment (% of total labor force) (modeled ILO estimate)]<>0), World[Unemployment (% of total labor force) (modeled ILO estimate)])),"No Value")} -> No Value | R12: {=IFERROR(MEDIAN( IF( (World[Country Name]=$I12)* (World[Year]=Year-2)* (World[Infant mortality rate (per 1,000 live births)]<>0), World[Infant mortality rate (per 1,000 live births)])),"No Value")} -> No Value | S12: {=IFERROR(MEDIAN( IF( (World[Country Name]=$I12)* (World[Year]=Year-2)* (World[Life expectancy at birth (years)]<>0), World[Life expectancy at birth (years)])),"No Value")} -> 73.738 | T12: {=IFERROR(MEDIAN( IF( (World[Country Name]=$I12)* (World[Year]=Year-2)* (World[GDP per capita (USD)]<>0), World[GDP per capita (USD)])),"No Value")} -> 19356.2 | U12: {=IFERROR(MEDIAN( IF( (World[Country Name]=$I12)* (World[Year]=Year-2)* (World[Unemployment (% of total labor force) (modeled ILO estimate)]<>0), World[Unemployment (% of total labor force) (modeled ILO estimate)])),"No Value")} -> No Value
A13: =Year-2 -> 1999 | B13: =_xlfn.XLOOKUP(Country,I2:I213,'Data Validation'!R2:R213) -> 26.45 | C13: =_xlfn.XLOOKUP(Country,I2:I213,'Data Validation'!S2:S213) -> 69.769 | D13: =_xlfn.XLOOKUP(Country,I2:I213,'Data Validation'!T2:T213) -> 2141.46 | E13: =_xlfn.XLOOKUP(Country,I2:I213,'Data Validation'!U2:U213)/100 -> 0.075165 | G13: 2008 | I13: Australia | J13: {=IFERROR(MEDIAN( IF( (World[Country Name]=$I13)* (World[Year]=Year)* (World[Infant mortality rate (per 1,000 live births)]<>0), World[Infant mortality rate (per 1,000 live births)])),"No Value")} -> 5 | K13: {=IFERROR(MEDIAN( IF( (World[Country Name]=$I13)* (World[Year]=Year)* (World[Life expectancy at birth (years)]<>0), World[Life expectancy at birth (years)])),"No data")} -> 79.6341 | L13: {=IFERROR(MEDIAN( IF( (World[Country Name]=$I13)* (World[Year]=Year)* (World[GDP per capita (USD)]<>0), World[GDP per capita (USD)])),"No Value")} -> 19490.9 | M13: {=IFERROR(MEDIAN( IF( (World[Country Name]=$I13)* (World[Year]=Year)* (World[Unemployment (% of total labor force) (modeled ILO estimate)]<>0), World[Unemployment (% of total labor force) (modeled ILO estimate)])),"No Value")} -> 6.742 | N13: {=IFERROR(MEDIAN( IF( (World[Country Name]=$I13)* (World[Year]=Year-1)* (World[Infant mortality rate (per 1,000 live births)]<>0), World[Infant mortality rate (per 1,000 live births)])),"No Value")} -> 5.1 | O13: {=IFERROR(MEDIAN( IF( (World[Country Name]=$I13)* (World[Year]=Year-1)* (World[Life expectancy at birth (years)]<>0), World[Life expectancy at birth (years)])),"No Value")} -> 79.2341 | P13: {=IFERROR(MEDIAN( IF( (World[Country Name]=$I13)* (World[Year]=Year-1)* (World[GDP per capita (USD)]<>0), World[GDP per capita (USD)])),"No Value")} -> 21679.2 | Q13: {=IFERROR(MEDIAN( IF( (World[Country Name]=$I13)* (World[Year]=Year-1)* (World[Unemployment (% of total labor force) (modeled ILO estimate)]<>0), World[Unemployment (% of total labor force) (modeled ILO estimate)])),"No Value")} -> 6.283 | R13: {=IFERROR(MEDIAN( IF( (World[Country Name]=$I13)* (World[Year]=Year-2)* (World[Infant mortality rate (per 1,000 live births)]<>0), World[Infant mortality rate (per 1,000 live births)])),"No Value")} -> 5.2 | S13: {=IFERROR(MEDIAN( IF( (World[Country Name]=$I13)* (World[Year]=Year-2)* (World[Life expectancy at birth (years)]<>0), World[Life expectancy at birth (years)])),"No Value")} -> 78.9317 | T13: {=IFERROR(MEDIAN( IF( (World[Country Name]=$I13)* (World[Year]=Year-2)* (World[GDP per capita (USD)]<>0), World[GDP per capita (USD)])),"No Value")} -> 20533 | U13: {=IFERROR(MEDIAN( IF( (World[Country Name]=$I13)* (World[Year]=Year-2)* (World[Unemployment (% of total labor force) (modeled ILO estimate)]<>0), World[Unemployment (% of total labor force) (modeled ILO estimate)])),"No Value")} -> 6.872
A14: =Year-1 -> 2000 | B14: =_xlfn.XLOOKUP(Country,I2:I213,'Data Validation'!N2:N213) -> 25.55 | C14: =_xlfn.XLOOKUP(Country,I2:I213,'Data Validation'!O2:O213) -> 70.36585 | D14: =_xlfn.XLOOKUP(Country,I2:I213,'Data Validation'!P2:P213) -> 2010 | E14: =_xlfn.XLOOKUP(Country,I2:I213,'Data Validation'!Q2:Q213)/100 -> 0.069635 | G14: 2007 | I14: Austria | J14: {=IFERROR(MEDIAN( IF( (World[Country Name]=$I14)* (World[Year]=Year)* (World[Infant mortality rate (per 1,000 live births)]<>0), World[Infant mortality rate (per 1,000 live births)])),"No Value")} -> 4.5 | K14: {=IFERROR(MEDIAN( IF( (World[Country Name]=$I14)* (World[Year]=Year)* (World[Life expectancy at birth (years)]<>0), World[Life expectancy at birth (years)])),"No data")} -> 78.5756 | L14: {=IFERROR(MEDIAN( IF( (World[Country Name]=$I14)* (World[Year]=Year)* (World[GDP per capita (USD)]<>0), World[GDP per capita (USD)])),"No Value")} -> 24537.5 | M14: {=IFERROR(MEDIAN( IF( (World[Country Name]=$I14)* (World[Year]=Year)* (World[Unemployment (% of total labor force) (modeled ILO estimate)]<>0), World[Unemployment (% of total labor force) (modeled ILO estimate)])),"No Value")} -> 4.007 | N14: {=IFERROR(MEDIAN( IF( (World[Country Name]=$I14)* (World[Year]=Year-1)* (World[Infant mortality rate (per 1,000 live births)]<>0), World[Infant mortality rate (per 1,000 live births)])),"No Value")} -> 4.6 | O14: {=IFERROR(MEDIAN( IF( (World[Country Name]=$I14)* (World[Year]=Year-1)* (World[Life expectancy at birth (years)]<>0), World[Life expectancy at birth (years)])),"No Value")} -> 78.1268 | P14: {=IFERROR(MEDIAN( IF( (World[Country Name]=$I14)* (World[Year]=Year-1)* (World[GDP per capita (USD)]<>0), World[GDP per capita (USD)])),"No Value")} -> 24564.5 | Q14: {=IFERROR(MEDIAN( IF( (World[Country Name]=$I14)* (World[Year]=Year-1)* (World[Unemployment (% of total labor force) (modeled ILO estimate)]<>0), World[Unemployment (% of total labor force) (modeled ILO estimate)])),"No Value")} -> 4.687 | R14: {=IFERROR(MEDIAN( IF( (World[Country Name]=$I14)* (World[Year]=Year-2)* (World[Infant mortality rate (per 1,000 live births)]<>0), World[Infant mortality rate (per 1,000 live births)])),"No Value")} -> 4.7 | S14: {=IFERROR(MEDIAN( IF( (World[Country Name]=$I14)* (World[Year]=Year-2)* (World[Life expectancy at birth (years)]<>0), World[Life expectancy at birth (years)])),"No Value")} -> 77.8756 | T14: {=IFERROR(MEDIAN( IF( (World[Country Name]=$I14)* (World[Year]=Year-2)* (World[GDP per capita (USD)]<>0), World[GDP per capita (USD)])),"No Value")} -> 27174.3 | U14: {=IFERROR(MEDIAN( IF( (World[Country Name]=$I14)* (World[Year]=Year-2)* (World[Unemployment (% of total labor force) (modeled ILO estimate)]<>0), World[Unemployment (% of total labor force) (modeled ILO estimate)])),"No Value")} -> 4.698
A15: =Year -> 2001 | B15: =_xlfn.XLOOKUP(Country,I2:I213,'Data Validation'!J2:J213) -> 25.15 | C15: =_xlfn.XLOOKUP(Country,I2:I213,'Data Validation'!K2:K213) -> 70.7735 | D15: =_xlfn.XLOOKUP(Country,I2:I213,'Data Validation'!L2:L213) -> 1925.54 | E15: =IFERROR(_xlfn.XLOOKUP(Country,I2:I213,'Data Validation'!M2:M213)/100,"No data") -> 0.072405 | G15: 2006 | I15: Azerbaijan | J15: {=IFERROR(MEDIAN( IF( (World[Country Name]=$I15)* (World[Year]=Year)* (World[Infant mortality rate (per 1,000 live births)]<>0), World[Infant mortality rate (per 1,000 live births)])),"No Value")} -> 57.5 | K15: {=IFERROR(MEDIAN( IF( (World[Country Name]=$I15)* (World[Year]=Year)* (World[Life expectancy at birth (years)]<>0), World[Life expectancy at birth (years)])),"No data")} -> 67.054 | L15: {=IFERROR(MEDIAN( IF( (World[Country Name]=$I15)* (World[Year]=Year)* (World[GDP per capita (USD)]<>0), World[GDP per capita (USD)])),"No Value")} -> 703.684 | M15: {=IFERROR(MEDIAN( IF( (World[Country Name]=$I15)* (World[Year]=Year)* (World[Unemployment (% of total labor force) (modeled ILO estimate)]<>0), World[Unemployment (% of total labor force) (modeled ILO estimate)])),"No Value")} -> 10.9 | N15: {=IFERROR(MEDIAN( IF( (World[Country Name]=$I15)* (World[Year]=Year-1)* (World[Infant mortality rate (per 1,000 live births)]<>0), World[Infant mortality rate (per 1,000 live births)])),"No Value")} -> 61.3 | O15: {=IFERROR(MEDIAN( IF( (World[Country Name]=$I15)* (World[Year]=Year-1)* (World[Life expectancy at birth (years)]<>0), World[Life expectancy at birth (years)])),"No Value")} -> 66.763 | P15: {=IFERROR(MEDIAN( IF( (World[Country Name]=$I15)* (World[Year]=Year-1)* (World[GDP per capita (USD)]<>0), World[GDP per capita (USD)])),"No Value")} -> 655.097 | Q15: {=IFERROR(MEDIAN( IF( (World[Country Name]=$I15)* (World[Year]=Year-1)* (World[Unemployment (% of total labor force) (modeled ILO estimate)]<>0), World[Unemployment (% of total labor force) (modeled ILO estimate)])),"No Value")} -> 11.8 | R15: {=IFERROR(MEDIAN( IF( (World[Country Name]=$I15)* (World[Year]=Year-2)* (World[Infant mortality rate (per 1,000 live births)]<>0), World[Infant mortality rate (per 1,000 live births)])),"No Value")} -> 65 | S15: {=IFERROR(MEDIAN( IF( (World[Country Name]=$I15)* (World[Year]=Year-2)* (World[Life expectancy at birth (years)]<>0), World[Life expectancy at birth (years)])),"No Value")} -> 66.491 | T15: {=IFERROR(MEDIAN( IF( (World[Country Name]=$I15)* (World[Year]=Year-2)* (World[GDP per capita (USD)]<>0), World[GDP per capita (USD)])),"No Value")} -> 573.893 | U15: {=IFERROR(MEDIAN( IF( (World[Country Name]=$I15)* (World[Year]=Year-2)* (World[Unemployment (% of total labor force) (modeled ILO estimate)]<>0), World[Unemployment (% of total labor force) (modeled ILO estimate)])),"No Value")} -> 10.9
G16: 2005 | I16: Bahamas, The | J16: {=IFERROR(MEDIAN( IF( (World[Country Name]=$I16)* (World[Year]=Year)* (World[Infant mortality rate (per 1,000 live births)]<>0), World[Infant mortality rate (per 1,000 live births)])),"No Value")} -> 12.8 | K16: {=IFERROR(MEDIAN( IF( (World[Country Name]=$I16)* (World[Year]=Year)* (World[Life expectancy at birth (years)]<>0), World[Life expectancy at birth (years)])),"No data")} -> 71.954 | L16: {=IFERROR(MEDIAN( IF( (World[Country Name]=$I16)* (World[Year]=Year)* (World[GDP per capita (USD)]<>0), World[GDP per capita (USD)])),"No Value")} -> 27486.2 | M16: {=IFERROR(MEDIAN( IF( (World[Country Name]=$I16)* (World[Year]=Year)* (World[Unemployment (% of total labor force) (modeled ILO estimate)]<>0), World[Unemployment (% of total labor force) (modeled ILO estimate)])),"No Value")} -> 6.87 | N16: {=IFERROR(MEDIAN( IF( (World[Country Name]=$I16)* (World[Year]=Year-1)* (World[Infant mortality rate (per 1,000 live births)]<>0), World[Infant mortality rate (per 1,000 live births)])),"No Value")} -> 13 | O16: {=IFERROR(MEDIAN( IF( (World[Country Name]=$I16)* (World[Year]=Year-1)* (World[Life expectancy at birth (years)]<>0), World[Life expectancy at birth (years)])),"No Value")} -> 71.914 | P16: {=IFERROR(MEDIAN( IF( (World[Country Name]=$I16)* (World[Year]=Year-1)* (World[GDP per capita (USD)]<>0), World[GDP per capita (USD)])),"No Value")} -> 27097.6 | Q16: {=IFERROR(MEDIAN( IF( (World[Country Name]=$I16)* (World[Year]=Year-1)* (World[Unemployment (% of total labor force) (modeled ILO estimate)]<>0), World[Unemployment (% of total labor force) (modeled ILO estimate)])),"No Value")} -> 7.153 | R16: {=IFERROR(MEDIAN( IF( (World[Country Name]=$I16)* (World[Year]=Year-2)* (World[Infant mortality rate (per 1,000 live births)]<>0), World[Infant mortality rate (per 1,000 live births)])),"No Value")} -> 13.2 | S16: {=IFERROR(MEDIAN( IF( (World[Country Name]=$I16)* (World[Year]=Year-2)* (World[Life expectancy at birth (years)]<>0), World[Life expectancy at birth (years)])),"No Value")} -> 71.858 | T16: {=IFERROR(MEDIAN( IF( (World[Country Name]=$I16)* (World[Year]=Year-2)* (World[GDP per capita (USD)]<>0), World[GDP per capita (USD)])),"No Value")} -> 26130.1 | U16: {=IFERROR(MEDIAN( IF( (World[Country Name]=$I16)* (World[Year]=Year-2)* (World[Unemployment (% of total labor force) (modeled ILO estimate)]<>0), World[Unemployment (% of total labor force) (modeled ILO estimate)])),"No Value")} -> 7.45
G17: 2004 | I17: Bahrain | J17: {=IFERROR(MEDIAN( IF( (World[Country Name]=$I17)* (World[Year]=Year)* (World[Infant mortality rate (per 1,000 live births)]<>0), World[Infant mortality rate (per 1,000 live births)])),"No Value")} -> 10.3 | K17: {=IFERROR(MEDIAN( IF( (World[Country Name]=$I17)* (World[Year]=Year)* (World[Life expectancy at birth (years)]<>0), World[Life expectancy at birth (years)])),"No data")} -> 74.635 | L17: {=IFERROR(MEDIAN( IF( (World[Country Name]=$I17)* (World[Year]=Year)* (World[GDP per capita (USD)]<>0), World[GDP per capita (USD)])),"No Value")} -> 12868.3 | M17: {=IFERROR(MEDIAN( IF( (World[Country Name]=$I17)* (World[Year]=Year)* (World[Unemployment (% of total labor force) (modeled ILO estimate)]<>0), World[Unemployment (% of total labor force) (modeled ILO estimate)])),"No Value")} -> 1.031 | N17: {=IFERROR(MEDIAN( IF( (World[Country Name]=$I17)* (World[Year]=Year-1)* (World[Infant mortality rate (per 1,000 live births)]<>0), World[Infant mortality rate (per 1,000 live births)])),"No Value")} -> 10.8 | O17: {=IFERROR(MEDIAN( IF( (World[Country Name]=$I17)* (World[Year]=Year-1)* (World[Life expectancy at birth (years)]<>0), World[Life expectancy at birth (years)])),"No Value")} -> 74.44 | P17: {=IFERROR(MEDIAN( IF( (World[Country Name]=$I17)* (World[Year]=Year-1)* (World[GDP per capita (USD)]<>0), World[GDP per capita (USD)])),"No Value")} -> 13636.4 | Q17: {=IFERROR(MEDIAN( IF( (World[Country Name]=$I17)* (World[Year]=Year-1)* (World[Unemployment (% of total labor force) (modeled ILO estimate)]<>0), World[Unemployment (% of total labor force) (modeled ILO estimate)])),"No Value")} -> 1.053 | R17: {=IFERROR(MEDIAN( IF( (World[Country Name]=$I17)* (World[Year]=Year-2)* (World[Infant mortality rate (per 1,000 live births)]<>0), World[Infant mortality rate (per 1,000 live births)])),"No Value")} -> 11.4 | S17: {=IFERROR(MEDIAN( IF( (World[Country Name]=$I17)* (World[Year]=Year-2)* (World[Life expectancy at birth (years)]<>0), World[Life expectancy at birth (years)])),"No Value")} -> 74.239 | T17: {=IFERROR(MEDIAN( IF( (World[Country Name]=$I17)* (World[Year]=Year-2)* (World[GDP per capita (USD)]<>0), World[GDP per capita (USD)])),"No Value")} -> 10401.5 | U17: {=IFERROR(MEDIAN( IF( (World[Country Name]=$I17)* (World[Year]=Year-2)* (World[Unemployment (% of total labor force) (modeled ILO estimate)]<>0), World[Unemployment (% of total labor force) (modeled ILO estimate)])),"No Value")} -> 1.079
B18: =TEXT(B15,"0.0")&" deaths" -> 25.2 deaths | C18: =TEXT(C15,"0.0")&" years" -> 70.8 years | G18: 2003 | I18: Bangladesh | J18: {=IFERROR(MEDIAN( IF( (World[Country Name]=$I18)* (World[Year]=Year)* (World[Infant mortality rate (per 1,000 live births)]<>0), World[Infant mortality rate (per 1,000 live births)])),"No Value")} -> 60.9 | K18: {=IFERROR(MEDIAN( IF( (World[Country Name]=$I18)* (World[Year]=Year)* (World[Life expectancy at birth (years)]<>0), World[Life expectancy at birth (years)])),"No data")} -> 65.956 | L18: {=IFERROR(MEDIAN( IF( (World[Country Name]=$I18)* (World[Year]=Year)* (World[GDP per capita (USD)]<>0), World[GDP per capita (USD)])),"No Value")} -> 415.034 | M18: {=IFERROR(MEDIAN( IF( (World[Country Name]=$I18)* (World[Year]=Year)* (World[Unemployment (% of total labor force) (modeled ILO estimate)]<>0), World[Unemployment (% of total labor force) (modeled ILO estimate)])),"No Value")} -> 3.551 | N18: {=IFERROR(MEDIAN( IF( (World[Country Name]=$I18)* (World[Year]=Year-1)* (World[Infant mortality rate (per 1,000 live births)]<>0), World[Infant mortality rate (per 1,000 live births)])),"No Value")} -> 63.9 | O18: {=IFERROR(MEDIAN( IF( (World[Country Name]=$I18)* (World[Year]=Year-1)* (World[Life expectancy at birth (years)]<>0), World[Life expectancy at birth (years)])),"No Value")} -> 65.447 | P18: {=IFERROR(MEDIAN( IF( (World[Country Name]=$I18)* (World[Year]=Year-1)* (World[GDP per capita (USD)]<>0), World[GDP per capita (USD)])),"No Value")} -> 418.069 | Q18: {=IFERROR(MEDIAN( IF( (World[Country Name]=$I18)* (World[Year]=Year-1)* (World[Unemployment (% of total labor force) (modeled ILO estimate)]<>0), World[Unemployment (% of total labor force) (modeled ILO estimate)])),"No Value")} -> 3.27 | R18: {=IFERROR(MEDIAN( IF( (World[Country Name]=$I18)* (World[Year]=Year-2)* (World[Infant mortality rate (per 1,000 live births)]<>0), World[Infant mortality rate (per 1,000 live births)])),"No Value")} -> 67 | S18: {=IFERROR(MEDIAN( IF( (World[Country Name]=$I18)* (World[Year]=Year-2)* (World[Life expectancy at birth (years)]<>0), World[Life expectancy at birth (years)])),"No Value")} -> 64.881 | T18: {=IFERROR(MEDIAN( IF( (World[Country Name]=$I18)* (World[Year]=Year-2)* (World[GDP per capita (USD)]<>0), World[GDP per capita (USD)])),"No Value")} -> 409.543 | U18: {=IFERROR(MEDIAN( IF( (World[Country Name]=$I18)* (World[Year]=Year-2)* (World[Unemployment (% of total labor force) (modeled ILO estimate)]<>0), World[Unemployment (% of total labor force) (modeled ILO estimate)])),"No Value")} -> 3.095
G19: 2002 | I19: Barbados | J19: {=IFERROR(MEDIAN( IF( (World[Country Name]=$I19)* (World[Year]=Year)* (World[Infant mortality rate (per 1,000 live births)]<>0), World[Infant mortality rate (per 1,000 live births)])),"No Value")} -> 14 | K19: {=IFERROR(MEDIAN( IF( (World[Country Name]=$I19)* (World[Year]=Year)* (World[Life expectancy at birth (years)]<>0), World[Life expectancy at birth (years)])),"No data")} -> 77.362 | L19: {=IFERROR(MEDIAN( IF( (World[Country Name]=$I19)* (World[Year]=Year)* (World[GDP per capita (USD)]<>0), World[GDP per capita (USD)])),"No Value")} -> 11437.2 | M19: {=IFERROR(MEDIAN( IF( (World[Country Name]=$I19)* (World[Year]=Year)* (World[Unemployment (% of total labor force) (modeled ILO estimate)]<>0), World[Unemployment (% of total labor force) (modeled ILO estimate)])),"No Value")} -> 9.85 | N19: {=IFERROR(MEDIAN( IF( (World[Country Name]=$I19)* (World[Year]=Year-1)* (World[Infant mortality rate (per 1,000 live births)]<>0), World[Infant mortality rate (per 1,000 live births)])),"No Value")} -> 13.7 | O19: {=IFERROR(MEDIAN( IF( (World[Country Name]=$I19)* (World[Year]=Year-1)* (World[Life expectancy at birth (years)]<>0), World[Life expectancy at birth (years)])),"No Value")} -> 77.162 | P19: {=IFERROR(MEDIAN( IF( (World[Country Name]=$I19)* (World[Year]=Year-1)* (World[GDP per capita (USD)]<>0), World[GDP per capita (USD)])),"No Value")} -> 11496.6 | Q19: {=IFERROR(MEDIAN( IF( (World[Country Name]=$I19)* (World[Year]=Year-1)* (World[Unemployment (% of total labor force) (modeled ILO estimate)]<>0), World[Unemployment (% of total labor force) (modeled ILO estimate)])),"No Value")} -> 9.35 | R19: {=IFERROR(MEDIAN( IF( (World[Country Name]=$I19)* (World[Year]=Year-2)* (World[Infant mortality rate (per 1,000 live births)]<>0), World[Infant mortality rate (per 1,000 live births)])),"No Value")} -> 13.6 | S19: {=IFERROR(MEDIAN( IF( (World[Country Name]=$I19)* (World[Year]=Year-2)* (World[Life expectancy at birth (years)]<>0), World[Life expectancy at birth (years)])),"No Value")} -> 76.933 | T19: {=IFERROR(MEDIAN( IF( (World[Country Name]=$I19)* (World[Year]=Year-2)* (World[GDP per capita (USD)]<>0), World[GDP per capita (USD)])),"No Value")} -> 11137.3 | U19: {=IFERROR(MEDIAN( IF( (World[Country Name]=$I19)* (World[Year]=Year-2)* (World[Unemployment (% of total labor force) (modeled ILO estimate)]<>0), World[Unemployment (% of total labor force) (modeled ILO estimate)])),"No Value")} -> 10.61
E20: ="Infant Mortality rate in "&Year&"|"&Country -> Infant Mortality rate in 2001|Global | G20: 2001 | I20: Belarus | J20: {=IFERROR(MEDIAN( IF( (World[Country Name]=$I20)* (World[Year]=Year)* (World[Infant mortality rate (per 1,000 live births)]<>0), World[Infant mortality rate (per 1,000 live births)])),"No Value")} -> 9.1 | K20: {=IFERROR(MEDIAN( IF( (World[Country Name]=$I20)* (World[Year]=Year)* (World[Life expectancy at birth (years)]<>0), World[Life expectancy at birth (years)])),"No data")} -> 68.5073 | L20: {=IFERROR(MEDIAN( IF( (World[Country Name]=$I20)* (World[Year]=Year)* (World[GDP per capita (USD)]<>0), World[GDP per capita (USD)])),"No Value")} -> 1244.37 | M20: {=IFERROR(MEDIAN( IF( (World[Country Name]=$I20)* (World[Year]=Year)* (World[Unemployment (% of total labor force) (modeled ILO estimate)]<>0), World[Unemployment (% of total labor force) (modeled ILO estimate)])),"No Value")} -> 11.314 | N20: {=IFERROR(MEDIAN( IF( (World[Country Name]=$I20)* (World[Year]=Year-1)* (World[Infant mortality rate (per 1,000 live births)]<>0), World[Infant mortality rate (per 1,000 live births)])),"No Value")} -> 9.9 | O20: {=IFERROR(MEDIAN( IF( (World[Country Name]=$I20)* (World[Year]=Year-1)* (World[Life expectancy at birth (years)]<>0), World[Life expectancy at birth (years)])),"No Value")} -> 68.9122 | P20: {=IFERROR(MEDIAN( IF( (World[Country Name]=$I20)* (World[Year]=Year-1)* (World[GDP per capita (USD)]<>0), World[GDP per capita (USD)])),"No Value")} -> 1276.29 | Q20: {=IFERROR(MEDIAN( IF( (World[Country Name]=$I20)* (World[Year]=Year-1)* (World[Unemployment (% of total labor force) (modeled ILO estimate)]<>0), World[Unemployment (% of total labor force) (modeled ILO estimate)])),"No Value")} -> 11.942 | R20: {=IFERROR(MEDIAN( IF( (World[Country Name]=$I20)* (World[Year]=Year-2)* (World[Infant mortality rate (per 1,000 live births)]<>0), World[Infant mortality rate (per 1,000 live births)])),"No Value")} -> 10.7 | S20: {=IFERROR(MEDIAN( IF( (World[Country Name]=$I20)* (World[Year]=Year-2)* (World[Life expectancy at birth (years)]<>0), World[Life expectancy at birth (years)])),"No Value")} -> 67.9073 | T20: {=IFERROR(MEDIAN( IF( (World[Country Name]=$I20)* (World[Year]=Year-2)* (World[GDP per capita (USD)]<>0), World[GDP per capita (USD)])),"No Value")} -> 1210.61 | U20: {=IFERROR(MEDIAN( IF( (World[Country Name]=$I20)* (World[Year]=Year-2)* (World[Unemployment (% of total labor force) (modeled ILO estimate)]<>0), World[Unemployment (% of total labor force) (modeled ILO estimate)])),"No Value")} -> 12.8
E21: ="Life Expectancy in "&Year&"|"&Country -> Life Expectancy in 2001|Global | G21: 2000 | I21: Belgium | J21: {=IFERROR(MEDIAN( IF( (World[Country Name]=$I21)* (World[Year]=Year)* (World[Infant mortality rate (per 1,000 live births)]<>0), World[Infant mortality rate (per 1,000 live births)])),"No Value")} -> 4.6 | K21: {=IFERROR(MEDIAN( IF( (World[Country Name]=$I21)* (World[Year]=Year)* (World[Life expectancy at birth (years)]<>0), World[Life expectancy at birth (years)])),"No data")} -> 77.9732 | L21: {=IFERROR(MEDIAN( IF( (World[Country Name]=$I21)* (World[Year]=Year)* (World[GDP per capita (USD)]<>0), World[GDP per capita (USD)])),"No Value")} -> 23121.6 | M21: {=IFERROR(MEDIAN( IF( (World[Country Name]=$I21)* (World[Year]=Year)* (World[Unemployment (% of total labor force) (modeled ILO estimate)]<>0), World[Unemployment (% of total labor force) (modeled ILO estimate)])),"No Value")} -> 6.177 | N21: {=IFERROR(MEDIAN( IF( (World[Country Name]=$I21)* (World[Year]=Year-1)* (World[Infant mortality rate (per 1,000 live births)]<>0), World[Infant mortality rate (per 1,000 live births)])),"No Value")} -> 4.8 | O21: {=IFERROR(MEDIAN( IF( (World[Country Name]=$I21)* (World[Year]=Year-1)* (World[Life expectancy at birth (years)]<>0), World[Life expectancy at birth (years)])),"No Value")} -> 77.722 | P21: {=IFERROR(MEDIAN( IF( (World[Country Name]=$I21)* (World[Year]=Year-1)* (World[GDP per capita (USD)]<>0), World[GDP per capita (USD)])),"No Value")} -> 23207.4 | Q21: {=IFERROR(MEDIAN( IF( (World[Country Name]=$I21)* (World[Year]=Year-1)* (World[Unemployment (% of total labor force) (modeled ILO estimate)]<>0), World[Unemployment (% of total labor force) (modeled ILO estimate)])),"No Value")} -> 6.586 | R21: {=IFERROR(MEDIAN( IF( (World[Country Name]=$I21)* (World[Year]=Year-2)* (World[Infant mortality rate (per 1,000 live births)]<>0), World[Infant mortality rate (per 1,000 live births)])),"No Value")} -> 5 | S21: {=IFERROR(MEDIAN( IF( (World[Country Name]=$I21)* (World[Year]=Year-2)* (World[Life expectancy at birth (years)]<>0), World[Life expectancy at birth (years)])),"No Value")} -> 77.6195 | T21: {=IFERROR(MEDIAN( IF( (World[Country Name]=$I21)* (World[Year]=Year-2)* (World[GDP per capita (USD)]<>0), World[GDP per capita (USD)])),"No Value")} -> 25444.1 | U21: {=IFERROR(MEDIAN( IF( (World[Country Name]=$I21)* (World[Year]=Year-2)* (World[Unemployment (% of total labor force) (modeled ILO estimate)]<>0), World[Unemployment (% of total labor force) (modeled ILO estimate)])),"No Value")} -> 8.649
